output/Console Output.txt




##########################
Scenario 1: No Trade Executed
##########################
C:\RANJAN KUMAR\RANJAN KUMAR\trading-exchange\exchange-client\build\libs>java -jar exchange-client-1.0.jar
May 04, 2025 5:12:01 PM com.beta.signal.trading.exchange.client.Client main
INFO: Client Connecting to exchange..

You are connected to the exchange, input(1/2/3):
1 : Place Order
2 : Cancel Order
3 : Quit
1
May 04, 2025 5:12:03 PM com.beta.signal.trading.exchange.client.Client handlePlaceOrder
INFO: Order Entry Format: [orderId],[B/S],[price],[quantity], e.g., 10006,B,105,16000
Type 'DONE' to finish or 'DISCONNECT' to exit.
10000,B,98,25500
10005,S,105,20000
10001,S,100,500
10002,S,100,10000
10003,B,99,50000
10004,S,103,100
DONE

C:\RANJAN KUMAR\RANJAN KUMAR\trading-exchange\exchange-matching-engine\build\libs>java -jar exchange-matching-engine-1.0.jar
Waiting on Client to connect and place new Order to be executed on Exchange!!
Starting Thread for Client - view-localhost


Order message from client view-localhost: [Ljava.lang.String;@5e4cdd77
50000 99        | 100 10500
25500 98        | 103 100
                | 105 20000


##########################
Scenario 2: Trade Executed
##########################
C:\RANJAN KUMAR\RANJAN KUMAR\trading-exchange\exchange-client\build\libs>java -jar exchange-client-1.0.jar
May 04, 2025 5:09:19 PM com.beta.signal.trading.exchange.client.Client main
INFO: Client Connecting to exchange..

You are connected to the exchange, input(1/2/3):
1 : Place Order
2 : Cancel Order
3 : Quit
1
May 04, 2025 5:09:20 PM com.beta.signal.trading.exchange.client.Client handlePlaceOrder
INFO: Order Entry Format: [orderId],[B/S],[price],[quantity], e.g., 10006,B,105,16000
Type 'DONE' to finish or 'DISCONNECT' to exit.
10000,B,98,25500
10005,S,105,20000
10001,S,100,500
10002,S,100,10000
10003,B,99,50000
10004,S,103,100
10006,B,105,16000
DONE

C:\RANJAN KUMAR\RANJAN KUMAR\trading-exchange\exchange-matching-engine\build\libs>java -jar exchange-matching-engine-1.0.jar
Waiting on Client to connect and place new Order to be executed on Exchange!!
Starting Thread for Client - view-localhost


Order message from client view-localhost: [Ljava.lang.String;@5e4cdd77
trade 10006,10001,100,500
trade 10006,10002,100,10000
trade 10006,10004,103,100
trade 10006,10005,105,5400
50000 99        | 105 14600
25500 98        |


##########################
Scenario 3: Iceberg Orders
##########################
C:\RANJAN KUMAR\RANJAN KUMAR\trading-exchange\exchange-client\build\libs>java -jar exchange-client-1.0.jar
May 04, 2025 5:21:12 PM com.beta.signal.trading.exchange.client.Client main
INFO: Client Connecting to exchange..
May 04, 2025 5:21:12 PM com.beta.signal.trading.exchange.client.Client printOptions
INFO:
You are connected to the exchange, input(1/2/3):
1 : Place Order
2 : Cancel Order
3 : Quit

1
May 04, 2025 5:21:13 PM com.beta.signal.trading.exchange.client.Client handlePlaceOrder
INFO: Order Entry Format: [orderId],[B/S],[price],[quantity], e.g., 10006,B,105,16000
Type 'DONE' to finish or 'DISCONNECT' to exit.
10000,B,98,25500
10005,S,101,20000
10002,S,100,10000
10001,S,100,7500
10003,B,99,50000
ice1,B,100,100000,10000
DONE

C:\RANJAN KUMAR\RANJAN KUMAR\trading-exchange\exchange-matching-engine\build\libs>java -jar exchange-matching-engine-1.0.jar
Waiting on Client to connect and place new Order to be executed on Exchange!!
Starting Thread for Client - view-localhost


May 04, 2025 5:21:28 PM handler.com.beta.signal.trading.exchange.engine.OrderMessageHandler run
INFO: Order message from client view-localhost: [10000,B,98,25500, 10005,S,101,20000, 10002,S,100,10000, 10001,S,100,7500, 10003,B,99,50000, ice1,B,100,100000,10000]
trade ice1,10002,100,10000
trade ice1,10001,100,7500
10000 100       | 101 20000
50000 99        |
25500 98        |
